Workbook

Sheet Hide
D1: Một | E1: Hai | F1: Ba | G1: Bốn | H1: Năm | I1: Sáu | J1: Bảy | K1: Tám | L1: Chín
D2: 1 | E2: 2 | F2: 3 | G2: 4 | H2: 5
A4: 1 | B4: =IFERROR(VLOOKUP($A4,MẪU!$A:$I,18,0),"") | C4: =IF(RIGHT("00000"&B4,5)="00000","",(RIGHT("00000"&B4,5))) | D4: =IF($C4="","",VALUE(MID($C4,D$2,1))) | E4: =IF($C4="","",VALUE(MID($C4,E$2,1))) | F4: =IF($C4="","",VALUE(MID($C4,F$2,1))) | G4: =IF($C4="","",VALUE(MID($C4,G$2,1))) | H4: =IF($C4="","",VALUE(MID($C4,H$2,1))) | J4: =IF($D4="","",IF(D4=0,IF(SUM($D4:D4)=0,"","Không"),CHOOSE(D4,$D$1,$E$1,$F$1,$G$1,$H$1,$I$1,$J$1,$K$1,$L$1))) | K4: =IF($D4="","",IF(E4=0,IF(SUM($D4:E4)=0,"","Không"),CHOOSE(E4,$D$1,$E$1,$F$1,$G$1,$H$1,$I$1,$J$1,$K$1,$L$1))) | L4: =IF($D4="","",IF(F4=0,IF(SUM($D4:F4)=0,"","Không"),CHOOSE(F4,$D$1,$E$1,$F$1,$G$1,$H$1,$I$1,$J$1,$K$1,$L$1))) | M4: =IF($D4="","",IF(G4=0,IF(SUM($D4:G4)=0,"","Không"),CHOOSE(G4,$D$1,$E$1,$F$1,$G$1,$H$1,$I$1,$J$1,$K$1,$L$1))) | N4: =IF($D4="","",IF(H4=0,IF(SUM($D4:H4)=0,"","Không"),CHOOSE(H4,$D$1,$E$1,$F$1,$G$1,$H$1,$I$1,$J$1,$K$1,$L$1))) | O4: =TRIM(J4&" "&K4&" "&L4&" "&M4&" "&N4)
A5: 2 | B5: =IFERROR(VLOOKUP($A5,MẪU!$A:$I,18,0),"") | C5: =IF(RIGHT("00000"&B5,5)="00000","",(RIGHT("00000"&B5,5))) | D5: =IF($C5="","",VALUE(MID($C5,D$2,1))) | E5: =IF($C5="","",VALUE(MID($C5,E$2,1))) | F5: =IF($C5="","",VALUE(MID($C5,F$2,1))) | G5: =IF($C5="","",VALUE(MID($C5,G$2,1))) | H5: =IF($C5="","",VALUE(MID($C5,H$2,1))) | J5: =IF($D5="","",IF(D5=0,IF(SUM($D5:D5)=0,"","Không"),CHOOSE(D5,$D$1,$E$1,$F$1,$G$1,$H$1,$I$1,$J$1,$K$1,$L$1))) | K5: =IF($D5="","",IF(E5=0,IF(SUM($D5:E5)=0,"","Không"),CHOOSE(E5,$D$1,$E$1,$F$1,$G$1,$H$1,$I$1,$J$1,$K$1,$L$1))) | L5: =IF($D5="","",IF(F5=0,IF(SUM($D5:F5)=0,"","Không"),CHOOSE(F5,$D$1,$E$1,$F$1,$G$1,$H$1,$I$1,$J$1,$K$1,$L$1))) | M5: =IF($D5="","",IF(G5=0,IF(SUM($D5:G5)=0,"","Không"),CHOOSE(G5,$D$1,$E$1,$F$1,$G$1,$H$1,$I$1,$J$1,$K$1,$L$1))) | N5: =IF($D5="","",IF(H5=0,IF(SUM($D5:H5)=0,"","Không"),CHOOSE(H5,$D$1,$E$1,$F$1,$G$1,$H$1,$I$1,$J$1,$K$1,$L$1))) | O5: =TRIM(J5&" "&K5&" "&L5&" "&M5&" "&N5)
A6: 3 | B6: =IFERROR(VLOOKUP($A6,MẪU!$A:$I,18,0),"") | C6: =IF(RIGHT("00000"&B6,5)="00000","",(RIGHT("00000"&B6,5))) | D6: =IF($C6="","",VALUE(MID($C6,D$2,1))) | E6: =IF($C6="","",VALUE(MID($C6,E$2,1))) | F6: =IF($C6="","",VALUE(MID($C6,F$2,1))) | G6: =IF($C6="","",VALUE(MID($C6,G$2,1))) | H6: =IF($C6="","",VALUE(MID($C6,H$2,1))) | J6: =IF($D6="","",IF(D6=0,IF(SUM($D6:D6)=0,"","Không"),CHOOSE(D6,$D$1,$E$1,$F$1,$G$1,$H$1,$I$1,$J$1,$K$1,$L$1))) | K6: =IF($D6="","",IF(E6=0,IF(SUM($D6:E6)=0,"","Không"),CHOOSE(E6,$D$1,$E$1,$F$1,$G$1,$H$1,$I$1,$J$1,$K$1,$L$1))) | L6: =IF($D6="","",IF(F6=0,IF(SUM($D6:F6)=0,"","Không"),CHOOSE(F6,$D$1,$E$1,$F$1,$G$1,$H$1,$I$1,$J$1,$K$1,$L$1))) | M6: =IF($D6="","",IF(G6=0,IF(SUM($D6:G6)=0,"","Không"),CHOOSE(G6,$D$1,$E$1,$F$1,$G$1,$H$1,$I$1,$J$1,$K$1,$L$1))) | N6: =IF($D6="","",IF(H6=0,IF(SUM($D6:H6)=0,"","Không"),CHOOSE(H6,$D$1,$E$1,$F$1,$G$1,$H$1,$I$1,$J$1,$K$1,$L$1))) | O6: =TRIM(J6&" "&K6&" "&L6&" "&M6&" "&N6)
A7: 4 | B7: =IFERROR(VLOOKUP($A7,MẪU!$A:$I,18,0),"") | C7: =IF(RIGHT("00000"&B7,5)="00000","",(RIGHT("00000"&B7,5))) | D7: =IF($C7="","",VALUE(MID($C7,D$2,1))) | E7: =IF($C7="","",VALUE(MID($C7,E$2,1))) | F7: =IF($C7="","",VALUE(MID($C7,F$2,1))) | G7: =IF($C7="","",VALUE(MID($C7,G$2,1))) | H7: =IF($C7="","",VALUE(MID($C7,H$2,1))) | J7: =IF($D7="","",IF(D7=0,IF(SUM($D7:D7)=0,"","Không"),CHOOSE(D7,$D$1,$E$1,$F$1,$G$1,$H$1,$I$1,$J$1,$K$1,$L$1))) | K7: =IF($D7="","",IF(E7=0,IF(SUM($D7:E7)=0,"","Không"),CHOOSE(E7,$D$1,$E$1,$F$1,$G$1,$H$1,$I$1,$J$1,$K$1,$L$1))) | L7: =IF($D7="","",IF(F7=0,IF(SUM($D7:F7)=0,"","Không"),CHOOSE(F7,$D$1,$E$1,$F$1,$G$1,$H$1,$I$1,$J$1,$K$1,$L$1))) | M7: =IF($D7="","",IF(G7=0,IF(SUM($D7:G7)=0,"","Không"),CHOOSE(G7,$D$1,$E$1,$F$1,$G$1,$H$1,$I$1,$J$1,$K$1,$L$1))) | N7: =IF($D7="","",IF(H7=0,IF(SUM($D7:H7)=0,"","Không"),CHOOSE(H7,$D$1,$E$1,$F$1,$G$1,$H$1,$I$1,$J$1,$K$1,$L$1))) | O7: =TRIM(J7&" "&K7&" "&L7&" "&M7&" "&N7)
A8: 5 | B8: =IFERROR(VLOOKUP($A8,MẪU!$A:$I,18,0),"") | C8: =IF(RIGHT("00000"&B8,5)="00000","",(RIGHT("00000"&B8,5))) | D8: =IF($C8="","",VALUE(MID($C8,D$2,1))) | E8: =IF($C8="","",VALUE(MID($C8,E$2,1))) | F8: =IF($C8="","",VALUE(MID($C8,F$2,1))) | G8: =IF($C8="","",VALUE(MID($C8,G$2,1))) | H8: =IF($C8="","",VALUE(MID($C8,H$2,1))) | J8: =IF($D8="","",IF(D8=0,IF(SUM($D8:D8)=0,"","Không"),CHOOSE(D8,$D$1,$E$1,$F$1,$G$1,$H$1,$I$1,$J$1,$K$1,$L$1))) | K8: =IF($D8="","",IF(E8=0,IF(SUM($D8:E8)=0,"","Không"),CHOOSE(E8,$D$1,$E$1,$F$1,$G$1,$H$1,$I$1,$J$1,$K$1,$L$1))) | L8: =IF($D8="","",IF(F8=0,IF(SUM($D8:F8)=0,"","Không"),CHOOSE(F8,$D$1,$E$1,$F$1,$G$1,$H$1,$I$1,$J$1,$K$1,$L$1))) | M8: =IF($D8="","",IF(G8=0,IF(SUM($D8:G8)=0,"","Không"),CHOOSE(G8,$D$1,$E$1,$F$1,$G$1,$H$1,$I$1,$J$1,$K$1,$L$1))) | N8: =IF($D8="","",IF(H8=0,IF(SUM($D8:H8)=0,"","Không"),CHOOSE(H8,$D$1,$E$1,$F$1,$G$1,$H$1,$I$1,$J$1,$K$1,$L$1))) | O8: =TRIM(J8&" "&K8&" "&L8&" "&M8&" "&N8)
A9: 6 | B9: =IFERROR(VLOOKUP($A9,MẪU!$A:$I,18,0),"") | C9: =IF(RIGHT("00000"&B9,5)="00000","",(RIGHT("00000"&B9,5))) | D9: =IF($C9="","",VALUE(MID($C9,D$2,1))) | E9: =IF($C9="","",VALUE(MID($C9,E$2,1))) | F9: =IF($C9="","",VALUE(MID($C9,F$2,1))) | G9: =IF($C9="","",VALUE(MID($C9,G$2,1))) | H9: =IF($C9="","",VALUE(MID($C9,H$2,1))) | J9: =IF($D9="","",IF(D9=0,IF(SUM($D9:D9)=0,"","Không"),CHOOSE(D9,$D$1,$E$1,$F$1,$G$1,$H$1,$I$1,$J$1,$K$1,$L$1))) | K9: =IF($D9="","",IF(E9=0,IF(SUM($D9:E9)=0,"","Không"),CHOOSE(E9,$D$1,$E$1,$F$1,$G$1,$H$1,$I$1,$J$1,$K$1,$L$1))) | L9: =IF($D9="","",IF(F9=0,IF(SUM($D9:F9)=0,"","Không"),CHOOSE(F9,$D$1,$E$1,$F$1,$G$1,$H$1,$I$1,$J$1,$K$1,$L$1))) | M9: =IF($D9="","",IF(G9=0,IF(SUM($D9:G9)=0,"","Không"),CHOOSE(G9,$D$1,$E$1,$F$1,$G$1,$H$1,$I$1,$J$1,$K$1,$L$1))) | N9: =IF($D9="","",IF(H9=0,IF(SUM($D9:H9)=0,"","Không"),CHOOSE(H9,$D$1,$E$1,$F$1,$G$1,$H$1,$I$1,$J$1,$K$1,$L$1))) | O9: =TRIM(J9&" "&K9&" "&L9&" "&M9&" "&N9)
A10: 7 | B10: =IFERROR(VLOOKUP($A10,MẪU!$A:$I,18,0),"") | C10: =IF(RIGHT("00000"&B10,5)="00000","",(RIGHT("00000"&B10,5))) | D10: =IF($C10="","",VALUE(MID($C10,D$2,1))) | E10: =IF($C10="","",VALUE(MID($C10,E$2,1))) | F10: =IF($C10="","",VALUE(MID($C10,F$2,1))) | G10: =IF($C10="","",VALUE(MID($C10,G$2,1))) | H10: =IF($C10="","",VALUE(MID($C10,H$2,1))) | J10: =IF($D10="","",IF(D10=0,IF(SUM($D10:D10)=0,"","Không"),CHOOSE(D10,$D$1,$E$1,$F$1,$G$1,$H$1,$I$1,$J$1,$K$1,$L$1))) | K10: =IF($D10="","",IF(E10=0,IF(SUM($D10:E10)=0,"","Không"),CHOOSE(E10,$D$1,$E$1,$F$1,$G$1,$H$1,$I$1,$J$1,$K$1,$L$1))) | L10: =IF($D10="","",IF(F10=0,IF(SUM($D10:F10)=0,"","Không"),CHOOSE(F10,$D$1,$E$1,$F$1,$G$1,$H$1,$I$1,$J$1,$K$1,$L$1))) | M10: =IF($D10="","",IF(G10=0,IF(SUM($D10:G10)=0,"","Không"),CHOOSE(G10,$D$1,$E$1,$F$1,$G$1,$H$1,$I$1,$J$1,$K$1,$L$1))) | N10: =IF($D10="","",IF(H10=0,IF(SUM($D10:H10)=0,"","Không"),CHOOSE(H10,$D$1,$E$1,$F$1,$G$1,$H$1,$I$1,$J$1,$K$1,$L$1))) | O10: =TRIM(J10&" "&K10&" "&L10&" "&M10&" "&N10)
A11: 8 | B11: =IFERROR(VLOOKUP($A11,MẪU!$A:$I,18,0),"") | C11: =IF(RIGHT("00000"&B11,5)="00000","",(RIGHT("00000"&B11,5))) | D11: =IF($C11="","",VALUE(MID($C11,D$2,1))) | E11: =IF($C11="","",VALUE(MID($C11,E$2,1))) | F11: =IF($C11="","",VALUE(MID($C11,F$2,1))) | G11: =IF($C11="","",VALUE(MID($C11,G$2,1))) | H11: =IF($C11="","",VALUE(MID($C11,H$2,1))) | J11: =IF($D11="","",IF(D11=0,IF(SUM($D11:D11)=0,"","Không"),CHOOSE(D11,$D$1,$E$1,$F$1,$G$1,$H$1,$I$1,$J$1,$K$1,$L$1))) | K11: =IF($D11="","",IF(E11=0,IF(SUM($D11:E11)=0,"","Không"),CHOOSE(E11,$D$1,$E$1,$F$1,$G$1,$H$1,$I$1,$J$1,$K$1,$L$1))) | L11: =IF($D11="","",IF(F11=0,IF(SUM($D11:F11)=0,"","Không"),CHOOSE(F11,$D$1,$E$1,$F$1,$G$1,$H$1,$I$1,$J$1,$K$1,$L$1))) | M11: =IF($D11="","",IF(G11=0,IF(SUM($D11:G11)=0,"","Không"),CHOOSE(G11,$D$1,$E$1,$F$1,$G$1,$H$1,$I$1,$J$1,$K$1,$L$1))) | N11: =IF($D11="","",IF(H11=0,IF(SUM($D11:H11)=0,"","Không"),CHOOSE(H11,$D$1,$E$1,$F$1,$G$1,$H$1,$I$1,$J$1,$K$1,$L$1))) | O11: =TRIM(J11&" "&K11&" "&L11&" "&M11&" "&N11)
A12: 9 | B12: =IFERROR(VLOOKUP($A12,MẪU!$A:$I,18,0),"") | C12: =IF(RIGHT("00000"&B12,5)="00000","",(RIGHT("00000"&B12,5))) | D12: =IF($C12="","",VALUE(MID($C12,D$2,1))) | E12: =IF($C12="","",VALUE(MID($C12,E$2,1))) | F12: =IF($C12="","",VALUE(MID($C12,F$2,1))) | G12: =IF($C12="","",VALUE(MID($C12,G$2,1))) | H12: =IF($C12="","",VALUE(MID($C12,H$2,1))) | J12: =IF($D12="","",IF(D12=0,IF(SUM($D12:D12)=0,"","Không"),CHOOSE(D12,$D$1,$E$1,$F$1,$G$1,$H$1,$I$1,$J$1,$K$1,$L$1))) | K12: =IF($D12="","",IF(E12=0,IF(SUM($D12:E12)=0,"","Không"),CHOOSE(E12,$D$1,$E$1,$F$1,$G$1,$H$1,$I$1,$J$1,$K$1,$L$1))) | L12: =IF($D12="","",IF(F12=0,IF(SUM($D12:F12)=0,"","Không"),CHOOSE(F12,$D$1,$E$1,$F$1,$G$1,$H$1,$I$1,$J$1,$K$1,$L$1))) | M12: =IF($D12="","",IF(G12=0,IF(SUM($D12:G12)=0,"","Không"),CHOOSE(G12,$D$1,$E$1,$F$1,$G$1,$H$1,$I$1,$J$1,$K$1,$L$1))) | N12: =IF($D12="","",IF(H12=0,IF(SUM($D12:H12)=0,"","Không"),CHOOSE(H12,$D$1,$E$1,$F$1,$G$1,$H$1,$I$1,$J$1,$K$1,$L$1))) | O12: =TRIM(J12&" "&K12&" "&L12&" "&M12&" "&N12)
A13: 10 | B13: =IFERROR(VLOOKUP($A13,MẪU!$A:$I,18,0),"") | C13: =IF(RIGHT("00000"&B13,5)="00000","",(RIGHT("00000"&B13,5))) | D13: =IF($C13="","",VALUE(MID($C13,D$2,1))) | E13: =IF($C13="","",VALUE(MID($C13,E$2,1))) | F13: =IF($C13="","",VALUE(MID($C13,F$2,1))) | G13: =IF($C13="","",VALUE(MID($C13,G$2,1))) | H13: =IF($C13="","",VALUE(MID($C13,H$2,1))) | J13: =IF($D13="","",IF(D13=0,IF(SUM($D13:D13)=0,"","Không"),CHOOSE(D13,$D$1,$E$1,$F$1,$G$1,$H$1,$I$1,$J$1,$K$1,$L$1))) | K13: =IF($D13="","",IF(E13=0,IF(SUM($D13:E13)=0,"","Không"),CHOOSE(E13,$D$1,$E$1,$F$1,$G$1,$H$1,$I$1,$J$1,$K$1,$L$1))) | L13: =IF($D13="","",IF(F13=0,IF(SUM($D13:F13)=0,"","Không"),CHOOSE(F13,$D$1,$E$1,$F$1,$G$1,$H$1,$I$1,$J$1,$K$1,$L$1))) | M13: =IF($D13="","",IF(G13=0,IF(SUM($D13:G13)=0,"","Không"),CHOOSE(G13,$D$1,$E$1,$F$1,$G$1,$H$1,$I$1,$J$1,$K$1,$L$1))) | N13: =IF($D13="","",IF(H13=0,IF(SUM($D13:H13)=0,"","Không"),CHOOSE(H13,$D$1,$E$1,$F$1,$G$1,$H$1,$I$1,$J$1,$K$1,$L$1))) | O13: =TRIM(J13&" "&K13&" "&L13&" "&M13&" "&N13)
A14: 11 | B14: =IFERROR(VLOOKUP($A14,MẪU!$A:$I,18,0),"") | C14: =IF(RIGHT("00000"&B14,5)="00000","",(RIGHT("00000"&B14,5))) | D14: =IF($C14="","",VALUE(MID($C14,D$2,1))) | E14: =IF($C14="","",VALUE(MID($C14,E$2,1))) | F14: =IF($C14="","",VALUE(MID($C14,F$2,1))) | G14: =IF($C14="","",VALUE(MID($C14,G$2,1))) | H14: =IF($C14="","",VALUE(MID($C14,H$2,1))) | J14: =IF($D14="","",IF(D14=0,IF(SUM($D14:D14)=0,"","Không"),CHOOSE(D14,$D$1,$E$1,$F$1,$G$1,$H$1,$I$1,$J$1,$K$1,$L$1))) | K14: =IF($D14="","",IF(E14=0,IF(SUM($D14:E14)=0,"","Không"),CHOOSE(E14,$D$1,$E$1,$F$1,$G$1,$H$1,$I$1,$J$1,$K$1,$L$1))) | L14: =IF($D14="","",IF(F14=0,IF(SUM($D14:F14)=0,"","Không"),CHOOSE(F14,$D$1,$E$1,$F$1,$G$1,$H$1,$I$1,$J$1,$K$1,$L$1))) | M14: =IF($D14="","",IF(G14=0,IF(SUM($D14:G14)=0,"","Không"),CHOOSE(G14,$D$1,$E$1,$F$1,$G$1,$H$1,$I$1,$J$1,$K$1,$L$1))) | N14: =IF($D14="","",IF(H14=0,IF(SUM($D14:H14)=0,"","Không"),CHOOSE(H14,$D$1,$E$1,$F$1,$G$1,$H$1,$I$1,$J$1,$K$1,$L$1))) | O14: =TRIM(J14&" "&K14&" "&L14&" "&M14&" "&N14)
A15: 12 | B15: =IFERROR(VLOOKUP($A15,MẪU!$A:$I,18,0),"") | C15: =IF(RIGHT("00000"&B15,5)="00000","",(RIGHT("00000"&B15,5))) | D15: =IF($C15="","",VALUE(MID($C15,D$2,1))) | E15: =IF($C15="","",VALUE(MID($C15,E$2,1))) | F15: =IF($C15="","",VALUE(MID($C15,F$2,1))) | G15: =IF($C15="","",VALUE(MID($C15,G$2,1))) | H15: =IF($C15="","",VALUE(MID($C15,H$2,1))) | J15: =IF($D15="","",IF(D15=0,IF(SUM($D15:D15)=0,"","Không"),CHOOSE(D15,$D$1,$E$1,$F$1,$G$1,$H$1,$I$1,$J$1,$K$1,$L$1))) | K15: =IF($D15="","",IF(E15=0,IF(SUM($D15:E15)=0,"","Không"),CHOOSE(E15,$D$1,$E$1,$F$1,$G$1,$H$1,$I$1,$J$1,$K$1,$L$1))) | L15: =IF($D15="","",IF(F15=0,IF(SUM($D15:F15)=0,"","Không"),CHOOSE(F15,$D$1,$E$1,$F$1,$G$1,$H$1,$I$1,$J$1,$K$1,$L$1))) | M15: =IF($D15="","",IF(G15=0,IF(SUM($D15:G15)=0,"","Không"),CHOOSE(G15,$D$1,$E$1,$F$1,$G$1,$H$1,$I$1,$J$1,$K$1,$L$1))) | N15: =IF($D15="","",IF(H15=0,IF(SUM($D15:H15)=0,"","Không"),CHOOSE(H15,$D$1,$E$1,$F$1,$G$1,$H$1,$I$1,$J$1,$K$1,$L$1))) | O15: =TRIM(J15&" "&K15&" "&L15&" "&M15&" "&N15)
... A1003: 1000 | B1003: =IFERROR(VLOOKUP($A1003,MẪU!$A:$I,18,0),"") | C1003: =IF(RIGHT("00000"&B1003,5)="00000","",(RIGHT("00000"&B1003,5))) | D1003: =IF($C1003="","",VALUE(MID($C1003,D$2,1))) | E1003: =IF($C1003="","",VALUE(MID($C1003,E$2,1))) | F1003: =IF($C1003="","",VALUE(MID($C1003,F$2,1))) | G1003: =IF($C1003="","",VALUE(MID($C1003,G$2,1))) | H1003: =IF($C1003="","",VALUE(MID($C1003,H$2,1))) | J1003: =IF($D1003="","",IF(D1003=0,IF(SUM($D1003:D1003)=0,"","Không"),CHOOSE(D1003,$D$1,$E$1,$F$1,$G$1,$H$1,$I$1,$J$1,$K$1,$L$1))) | K1003: =IF($D1003="","",IF(E1003=0,IF(SUM($D1003:E1003)=0,"","Không"),CHOOSE(E1003,$D$1,$E$1,$F$1,$G$1,$H$1,$I$1,$J$1,$K$1,$L$1))) | L1003: =IF($D1003="","",IF(F1003=0,IF(SUM($D1003:F1003)=0,"","Không"),CHOOSE(F1003,$D$1,$E$1,$F$1,$G$1,$H$1,$I$1,$J$1,$K$1,$L$1))) | M1003: =IF($D1003="","",IF(G1003=0,IF(SUM($D1003:G1003)=0,"","Không"),CHOOSE(G1003,$D$1,$E$1,$F$1,$G$1,$H$1,$I$1,$J$1,$K$1,$L$1))) | N1003: =IF($D1003="","",IF(H1003=0,IF(SUM($D1003:H1003)=0,"","Không"),CHOOSE(H1003,$D$1,$E$1,$F$1,$G$1,$H$1,$I$1,$J$1,$K$1,$L$1))) | O1003: =TRIM(J1003&" "&K1003&" "&L1003&" "&M1003&" "&N1003)

Sheet MẪU
A1: TT | B1: dòng 1 loại hàng | C1: dòng 2 loại hàng | D1: dòng 3 loại hàng | E1: dòng 1 khối lượng | F1: dòng 2 khối lượng | G1: dòng 3 khối lượng | H1: MDSD | I1: TKL | J1: TONG SO VIET BANG CHU | K1: TEN NHAN HANG | L1: NOI DEN CUOI CUNG | M1: MSDK | N1: BIEN KIEM SOAT | O1: SO THUNG | P1: CAC VAT DUNG KHAC CO LIEN QUAN | Q1: NGAY | R1: CO GIA TRI DEN NGAY
B2: Gà Pha Lóc | C2: Gà Pha Lóc DL | D2: Chưa có nhóm | E2: 30 | F2: 165 | G2: 30 | H2: Thực Phẩm | I2: 195 | J2: Một Trăm Chín Mươi Lăm | K2: FS HUỲNH THÚC KHÁNG NHA TRANG 0779971504 | L2: Số 101 Huỳnh Thúc Kháng, Phường Tân Tiến, Tỉnh Khánh Hòa | N2: 60C52202 | Q2: 08/07/2026
B3: Gà Pha Lóc DL | C3: Chưa có nhóm | E3: 75 | F3: 10 | H3: Thực Phẩm | I3: 80 | J3: Tám Mươi | K3: FS VĨNH HẢI, NHA TRANG Ms Tiến 0984140598 | L3: Số 436 Đường 2/4, Phường Bắc Nha Trang, Tỉnh, Tỉnh Khánh Hòa | N3: 60C52202 | Q3: 08/07/2026
B4: Gà Pha Lóc DL | C4: Chưa có nhóm | E4: 30 | F4: 20 | H4: Thực Phẩm | I4: 40 | J4: Bốn Mươi | K4: FS Vĩnh Nguyên Ms Vân 0901627715 | L4: Lô 68, khu b đường QH2, khóm trường sơn, Phường Nha Trang, Tỉnh Khánh Hòa | N4: 60C52202 | Q4: 08/07/2026

Sheet DANH SÁCH KH
A1: DANH SÁCH KHÁCH HÀNG FOOD CA NGÀY
A2: 1 | B2: Kho lạnh ABA Sài Gòn | C2: 18-20 đường Trung Tâm KCN Tân Tạo, P. Tân Tạo A, Q. Bình Tân, HCM
A3: 2 | B3: Địa điểm Kinh doanh Công ty Cổ Phần Thế Giới Di Động Số 1 | C3: Lô 87 Khu chế xuất Linh Trung II, phường Bình Chiểu, Thành phố Thủ Đức, TP.HCM, Việt Nam
A4: 3 | B4: Địa điểm Kinh doanh Công ty Cổ Phần Thế Giới Di Động Số 1 | C4: G16/108A, đường Trần Đại Nghĩa, Ấp 7, xã Lê Minh Xuân, Huyện Bình Chánh, Thành phố HCM, Việt Nam
A5: 4 | B5: CÔNG TY CP CHĂN NUÔI CP VIỆT NAM -Chi Nhánh NM 4 Đồng Nai | C5: Lô 13, KCN Biên Hòa 2, P. Trấn Biên, T. Đồng Nai
A6: 5 | B6: Cty TNHH Jollibee Việt Nam Tại Cần Giuộc | C6: Lô K3-1 và K3-3 KCN Tân Kim mở rộng, TT. Cần Giuộc, H.Cần Giuộc,Tỉnh Long An
A7: 6 | B7: Kho Lạnh ECV | C7: Số 18, Đường 6 , KCN Sóng Thần, Dĩ An, Bình Dương
A8: 7 | B8: CÔNG TY QUANG MINH | C8: 36/1B Khu Đồng An, P. Bình Hòa, Thuận An, Bình Dương
A9: 8 | B9: CTY TNHH MEITO VN | C9: Lô G, Đường 6, KCN Sóng Thần 2, Dĩ An, Bình Dương
A10: 9 | B10: Hoàng Đình Quân | C10: KDC Vĩnh Phú, Thuận An, Bình Dương
A11: 10 | B11: Công ty TNHH Xây Dựng và Dịch Vụ An Thiên Lý | C11: Tổ 10 Ấp Cây Xoài, Tân An, Vĩnh Cửu, Đồng Nai
A12: 11 | B12: Công ty TNHH Ẩm Thực Khẩu Vị | C12: Ấp Dân Thắng 1, X. Tân Thới Nhì, Hóc Môn, HCM
A13: 12 | B13: Công ty TNHH Một Thành Viên Hoàng Hoàng Thủy | C13: Khu phố 2, P. Long Bình, Biên Hòa, Đồng Nai
... A28: 27 | B28: Công Ty CP VN Chi Nhánh 3 tại TP.HCM | C28: Lô C4-3, đường D5 và Lô C4-4, đường N10,KCN Tân Phú Trung, X. Củ Chi, TP. HCM
B29: Chi Nhánh Công Ty Cổ Phần Chăn Nuôi C.P. Việt Nam -Nhà Máy Chế Biến Sản Phẩm Thịt Hà Nội | C29: Lô CN - B3, KCN Phú Nghĩa, Xã Phú Nghĩa,H.Chương Mỹ, TP.Hà Nội, VN
B30: Nguyễn Thanh Phụng | C30: Mỹ Phú Đất Liền, TT.Mỹ Thọ, Cao Lãnh, Đồng Tháp
B31: CTY CP KingFood Market | C31: Lô 87 Khu chế xuất Linh Trung II, phường Bình Chiểu, Thành phố Thủ Đức, TP.HCM, Việt Nam
B32: KING FOOD KHO ABA | C32: KHO ABA MIỀN ĐÔNG, LÔ 87 - KHU CHẾ XUẤT & CÔNG NGHIỆP LINH TRUNG 2 - PHƯỜNG BÌNH CHIỂU - THÀNH PHỐ THỦ ĐỨC - TP HỒ CHÍ MINH
B33: CÔNG TY TNHH MTV AJ TOTAL VIỆT NAM – CHI NHÁNH PHỐ NỐI | C33: Đường 206, Khu F, Khu công nghiệp Phố Nối A, Xã Minh Hải, Huyện Văn Lâm, Tỉnh Hưng Yên, Việt Nam.
B34: CTY CP Seven System Việt Nam | C34: Lô D2, KCN Tân Phú Trung, X Tân Phú Trung, H.Củ Chi, Tp.HCM
B35: Kho Đức Hưng 2 | C35: KCN Phú Nghĩa, Chương Mỹ, Hà Nội
B36: Công Ty Cổ Phần Thực Phẩm Đông Nam Á | C36: 271 Bạch Đằng, P. 15, Q. Bình Thạnh, TP HCM
B37: ĐỊA ĐIỂM KINH DOANH DC QUẬN 2 - CTY TNHH CPV FOOD | C37: Số 83/10, Đường 6, Tổ 40, Khu phố 4, Phường An Khánh, Tp Hồ Chí Minh, Việt Nam.
B38: Trạm Kiểm dịch: Quốc Lộ 13 - Mỹ Phước Tân Vạn - Ngã tư Phạm Ngọc Thạch - Cầu Ông Bố - KCN Sóng Thần
B39: HOÀNG ĐÌNH QUÂN | C39: D1, 55 KDC TÂN VŨ MINH, P. VĨNH PHÚ, THUẬN AN, BÌNH DƯƠNG
B40: HKD Vựa Gà Mỹ Châu | C40: Số 28, Nguyên Doãn Phong, Mỹ Phú, Cao Lãnh, Đồng Tháp
B41: CTY Khải Minh Fresh Food | C41: 98/6A KP Long Điềm,P.Long Bình Tân, TP.Biên Hòa, Đồng Nai
B42: Nguyễn Minh Tâm | C42: 1120 Quốc Lộ 1A, P.Tân Tạo, TP.HCM
B43: Vũ Thị Ngọc Chi | C43: 5/11 KP8, P.Long Bình, TP.Biên Hòa, T.Đồng Nai
B44: Nguyễn Việt Hoàng | C44: Ấp Hòa Phú IV, TT.An Châu, H.Châu Thành, T.An Giang
B45: Công Ty TNHH Vietsan Food | C45: 1505/63A/2 Khu Phố 3, P.Tân Hạnh, Tp.Biên Hòa, Đồng Nai
B46: CTY TNHH Thức Ăn Chăn Nuôi Thiên An | C46: B1/16A Hưng Nhơn, Tân Kiên, Bình Chánh
B47: Công Ty Cổ Phần Thực Phẩm Đông Nam Á | C47: E6/168 Liên Ấp 4-5 Tổ 6 Ấp 5, X. Đa Phước, H.Bình Chánh, TP.HCM
B48: CTY TNHH Lineage Logistics VN | C48: 18 Đường số 6, KCN Sóng Thần 1- Dĩ An-Bình Dương
B49: CTY LỘC VẠN XUÂN | C49: 165/38 Đường Thạnh Lộc 41 , P.Thạnh Lộc Q12, TP.HCM
B50: CTY TNHH TMDV Thưc Phẩm Tiến Thành | C50: 2/9 Nguyễn Thị Pha, Ấp 6, Đông Thạnh, H.Hooc Môn
... B57: CTY TNHH Thức Ăn Chăn Nuôi Thiên An | C57: E7/6C ĐƯỜNG VÕ HỮU LƠI, Ấp 5, X. Bình Lợi, Tp.HCM
C58: 1478 BÙI HỮU NGHĨA KP3, P .BIÊN HÒA, T.ĐỒNG NAI
B59: CTY TNHH MTV SX TM DV XNK NGÂN THIÊN NAM | C59: Số 113/1 Trần Quang Khải, Khóm Trung An, P.Mỹ Thới, An Giang
B60: Công Ty TNHH MTV AJ Total Việt Nam – Chi Nhánh Đồng Nai | C60: KCN Nhơn Trạch 6, xã Phước An, tỉnh Đồng Nai
...
